Traceback (most recent call last):
  File "/home/renato/anaconda3/lib/python3.8/site-packages/dask/dataframe/utils.py", line 173, in raise_on_meta_error
    yield
  File "/home/renato/anaconda3/lib/python3.8/site-packages/dask/dataframe/core.py", line 5125, in _emulate
    return func(*_extract_meta(args, True), **_extract_meta(kwargs, True))
  File "/home/renato/anaconda3/lib/python3.8/site-packages/pandas/core/ops/__init__.py", line 570, in flex_wrapper
    return self._binop(other, op, level=level, fill_value=fill_value)
  File "/home/renato/anaconda3/lib/python3.8/site-packages/pandas/core/series.py", line 2618, in _binop
    result = func(this_vals, other_vals)
TypeError: unsupported operand type(s) for -: 'str' and 'str'

The above exception was the direct cause of the following exception:

Traceback (most recent call last):
  File "var_builder.py", line 135, in <module>
    df['cit_delay']=df['patent_date'].sub(df['citation_date'], axis=0)
  File "/home/renato/anaconda3/lib/python3.8/site-packages/dask/dataframe/core.py", line 3109, in meth
    meta = _emulate(op, self, other, axis=axis, fill_value=fill_value)
  File "/home/renato/anaconda3/lib/python3.8/site-packages/dask/dataframe/core.py", line 5125, in _emulate
    return func(*_extract_meta(args, True), **_extract_meta(kwargs, True))
  File "/home/renato/anaconda3/lib/python3.8/contextlib.py", line 131, in __exit__
    self.gen.throw(type, value, traceback)
  File "/home/renato/anaconda3/lib/python3.8/site-packages/dask/dataframe/utils.py", line 194, in raise_on_meta_error
    raise ValueError(msg) from e
ValueError: Metadata inference failed in `sub`.

Original error is below:
------------------------
TypeError("unsupported operand type(s) for -: 'str' and 'str'")

Traceback:
---------
  File "/home/renato/anaconda3/lib/python3.8/site-packages/dask/dataframe/utils.py", line 173, in raise_on_meta_error
    yield
  File "/home/renato/anaconda3/lib/python3.8/site-packages/dask/dataframe/core.py", line 5125, in _emulate
    return func(*_extract_meta(args, True), **_extract_meta(kwargs, True))
  File "/home/renato/anaconda3/lib/python3.8/site-packages/pandas/core/ops/__init__.py", line 570, in flex_wrapper
    return self._binop(other, op, level=level, fill_value=fill_value)
  File "/home/renato/anaconda3/lib/python3.8/site-packages/pandas/core/series.py", line 2618, in _binop
    result = func(this_vals, other_vals)

Traceback (most recent call last):
  File "var_builder.py", line 121, in <module>
    df.citation_date.map_partitions(pd.to_datetime, meta=meta)
  File "/home/renato/anaconda3/lib/python3.8/site-packages/dask/dataframe/core.py", line 642, in map_partitions
    return map_partitions(func, self, *args, **kwargs)
  File "/home/renato/anaconda3/lib/python3.8/site-packages/dask/dataframe/core.py", line 5177, in map_partitions
    meta = make_meta(meta, index=meta_index)
  File "/home/renato/anaconda3/lib/python3.8/site-packages/dask/utils.py", line 507, in __call__
    return meth(arg, *args, **kwargs)
  File "/home/renato/anaconda3/lib/python3.8/site-packages/dask/dataframe/utils.py", line 338, in make_meta_object
    return _empty_series(x[0], x[1], index=index)
  File "/home/renato/anaconda3/lib/python3.8/site-packages/dask/dataframe/utils.py", line 282, in _empty_series
    return pd.Series([], dtype=dtype, name=name, index=index)
  File "/home/renato/anaconda3/lib/python3.8/site-packages/pandas/core/series.py", line 220, in __init__
    dtype = self._validate_dtype(dtype)
  File "/home/renato/anaconda3/lib/python3.8/site-packages/pandas/core/generic.py", line 259, in _validate_dtype
    dtype = pandas_dtype(dtype)
  File "/home/renato/anaconda3/lib/python3.8/site-packages/pandas/core/dtypes/common.py", line 1889, in pandas_dtype
    raise TypeError(f"dtype '{dtype}' not understood")
TypeError: dtype '<class 'pandas._libs.tslibs.timestamps.Timestamp'>' not understood
Traceback (most recent call last):
  File "var_builder.py", line 121, in <module>
    df.citation_date.map_partitions(pd.to_pydatetime, meta=meta)
  File "/home/renato/anaconda3/lib/python3.8/site-packages/pandas/__init__.py", line 263, in __getattr__
    raise AttributeError(f"module 'pandas' has no attribute '{name}'")
AttributeError: module 'pandas' has no attribute 'to_pydatetime'
Traceback (most recent call last):
  File "var_builder.py", line 121, in <module>
    df.citation_date.map_partitions(pd.dt.to_pydatetime, meta=meta)
  File "/home/renato/anaconda3/lib/python3.8/site-packages/pandas/__init__.py", line 263, in __getattr__
    raise AttributeError(f"module 'pandas' has no attribute '{name}'")
AttributeError: module 'pandas' has no attribute 'dt'
Traceback (most recent call last):
  File "var_builder.py", line 121, in <module>
    df.citation_date.map_partitions(dd.to_datetime, meta=meta)
  File "/home/renato/anaconda3/lib/python3.8/site-packages/dask/dataframe/core.py", line 642, in map_partitions
    return map_partitions(func, self, *args, **kwargs)
  File "/home/renato/anaconda3/lib/python3.8/site-packages/dask/dataframe/core.py", line 5177, in map_partitions
    meta = make_meta(meta, index=meta_index)
  File "/home/renato/anaconda3/lib/python3.8/site-packages/dask/utils.py", line 507, in __call__
    return meth(arg, *args, **kwargs)
  File "/home/renato/anaconda3/lib/python3.8/site-packages/dask/dataframe/utils.py", line 338, in make_meta_object
    return _empty_series(x[0], x[1], index=index)
  File "/home/renato/anaconda3/lib/python3.8/site-packages/dask/dataframe/utils.py", line 282, in _empty_series
    return pd.Series([], dtype=dtype, name=name, index=index)
  File "/home/renato/anaconda3/lib/python3.8/site-packages/pandas/core/series.py", line 220, in __init__
    dtype = self._validate_dtype(dtype)
  File "/home/renato/anaconda3/lib/python3.8/site-packages/pandas/core/generic.py", line 259, in _validate_dtype
    dtype = pandas_dtype(dtype)
  File "/home/renato/anaconda3/lib/python3.8/site-packages/pandas/core/dtypes/common.py", line 1889, in pandas_dtype
    raise TypeError(f"dtype '{dtype}' not understood")
TypeError: dtype '<class 'pandas._libs.tslibs.timestamps.Timestamp'>' not understood
[I 16:00:29.896 NotebookApp] JupyterLab extension loaded from /home/renato/anaconda3/lib/python3.8/site-packages/jupyterlab
[I 16:00:29.905 NotebookApp] JupyterLab application directory is /home/renato/anaconda3/share/jupyter/lab
[I 16:00:29.910 NotebookApp] Serving notebooks from local directory: /home/renato/RESEARCH/patent_analysis
[I 16:00:29.910 NotebookApp] The Jupyter Notebook is running at:
[I 16:00:29.910 NotebookApp] http://localhost:8888/?token=e58f4562edf601e66dcea05cbbe9170ad7cd242e50895845
[I 16:00:29.910 NotebookApp]  or http://127.0.0.1:8888/?token=e58f4562edf601e66dcea05cbbe9170ad7cd242e50895845
[I 16:00:29.910 NotebookApp] Use Control-C to stop this server and shut down all kernels (twice to skip confirmation).
[W 16:00:29.961 NotebookApp] No web browser found: could not locate runnable browser.
[C 16:00:29.961 NotebookApp] 
    
    To access the notebook, open this file in a browser:
        file:///home/renato/.local/share/jupyter/runtime/nbserver-3195-open.html
    Or copy and paste one of these URLs:
        http://localhost:8888/?token=e58f4562edf601e66dcea05cbbe9170ad7cd242e50895845
     or http://127.0.0.1:8888/?token=e58f4562edf601e66dcea05cbbe9170ad7cd242e50895845
[W 16:00:56.826 NotebookApp] 404 GET /api/contents/RESEARCH/patent_analysis/var_builder.py?content=0&_=1603995501617 (127.0.0.1): No such file or directory: RESEARCH/patent_analysis/var_builder.py
[W 16:00:56.826 NotebookApp] No such file or directory: RESEARCH/patent_analysis/var_builder.py
[W 16:00:56.827 NotebookApp] 404 GET /api/contents/RESEARCH/patent_analysis/var_builder.py?content=0&_=1603995501617 (127.0.0.1) 2.32ms referer=http://localhost:8080/edit/RESEARCH/patent_analysis/var_builder.py
[I 16:00:56.963 NotebookApp] Uploading file to /RESEARCH/patent_analysis/var_builder.py
[E 16:00:56.963 NotebookApp] Error while saving file: RESEARCH/patent_analysis/var_builder.py [Errno 2] No such file or directory: '/home/renato/RESEARCH/patent_analysis/RESEARCH/patent_analysis/var_builder.py'
    Traceback (most recent call last):
      File "/home/renato/anaconda3/lib/python3.8/site-packages/notebook/services/contents/filemanager.py", line 473, in save
        self._save_file(os_path, model['content'], model.get('format'))
      File "/home/renato/anaconda3/lib/python3.8/site-packages/notebook/services/contents/fileio.py", line 340, in _save_file
        with self.atomic_writing(os_path, text=False) as f:
      File "/home/renato/anaconda3/lib/python3.8/contextlib.py", line 113, in __enter__
        return next(self.gen)
      File "/home/renato/anaconda3/lib/python3.8/site-packages/notebook/services/contents/fileio.py", line 210, in atomic_writing
        with atomic_writing(os_path, *args, log=self.log, **kwargs) as f:
      File "/home/renato/anaconda3/lib/python3.8/contextlib.py", line 113, in __enter__
        return next(self.gen)
      File "/home/renato/anaconda3/lib/python3.8/site-packages/notebook/services/contents/fileio.py", line 107, in atomic_writing
        fileobj = io.open(path, 'wb', **kwargs)
    FileNotFoundError: [Errno 2] No such file or directory: '/home/renato/RESEARCH/patent_analysis/RESEARCH/patent_analysis/var_builder.py'
[W 16:00:57.015 NotebookApp] 500 PUT /api/contents/RESEARCH/patent_analysis/var_builder.py (127.0.0.1): Unexpected error while saving file: RESEARCH/patent_analysis/var_builder.py [Errno 2] No such file or directory: '/home/renato/RESEARCH/patent_analysis/RESEARCH/patent_analysis/var_builder.py'
[W 16:00:57.015 NotebookApp] Unexpected error while saving file: RESEARCH/patent_analysis/var_builder.py [Errno 2] No such file or directory: '/home/renato/RESEARCH/patent_analysis/RESEARCH/patent_analysis/var_builder.py'
[E 16:00:57.015 NotebookApp] {
      "Host": "localhost:8080",
      "User-Agent": "Mozilla/5.0 (Windows NT 10.0; Win64; x64; rv:81.0) Gecko/20100101 Firefox/81.0",
      "Accept": "application/json, text/javascript, */*; q=0.01",
      "Accept-Language": "en-US,en;q=0.5",
      "Accept-Encoding": "gzip, deflate",
      "Content-Type": "application/json",
      "X-Xsrftoken": "2|94322795|9b744c6c8443ddb7fe8a96900e6941bd|1602879623",
      "X-Requested-With": "XMLHttpRequest",
      "Content-Length": "6536",
      "Origin": "http://localhost:8080",
      "Dnt": "1",
      "Connection": "keep-alive",
      "Referer": "http://localhost:8080/edit/RESEARCH/patent_analysis/var_builder.py",
      "Cookie": "_xsrf=2|94322795|9b744c6c8443ddb7fe8a96900e6941bd|1602879623; username-localhost-8889=\"2|1:0|10:1602880293|23:username-localhost-8889|44:ZTk0ZjZlMjBjNmE2NDBlN2E3MzY4NzZiNjcyMGExOWI=|c8e7b5827ac161b9b1bf5693eff5020dc0ff1c3041668a70337f594353019564\"; username-localhost-8888=\"2|1:0|10:1603199253|23:username-localhost-8888|44:ZTM4ODI4NTE4NzljNGRhYjg1NzEyZGYyM2Y4ZTE2MGU=|2c39263755d5ff95b3fe6816fe188c8144c17e122238d8b9124912c41a0eb93a\"; username-localhost-8080=\"2|1:0|10:1603888623|23:username-localhost-8080|44:ZDZmM2RhZmVlMjI2NDg3ZDkwN2EwOWY4NjRhMjMxYzY=|67f005c42871523e09257b8463cad5385acf0ed6228ef2a92a8340b3e377a94d\""
    }
[E 16:00:57.016 NotebookApp] 500 PUT /api/contents/RESEARCH/patent_analysis/var_builder.py (127.0.0.1) 53.76ms referer=http://localhost:8080/edit/RESEARCH/patent_analysis/var_builder.py
[W 16:01:48.267 NotebookApp] 404 GET /api/contents/RESEARCH/patent_analysis/var_builder.py?content=0&_=1603995501618 (127.0.0.1): No such file or directory: RESEARCH/patent_analysis/var_builder.py
[W 16:01:48.267 NotebookApp] No such file or directory: RESEARCH/patent_analysis/var_builder.py
[W 16:01:48.267 NotebookApp] 404 GET /api/contents/RESEARCH/patent_analysis/var_builder.py?content=0&_=1603995501618 (127.0.0.1) 1.65ms referer=http://localhost:8080/edit/RESEARCH/patent_analysis/var_builder.py
[I 16:01:48.300 NotebookApp] Uploading file to /RESEARCH/patent_analysis/var_builder.py
[E 16:01:48.300 NotebookApp] Error while saving file: RESEARCH/patent_analysis/var_builder.py [Errno 2] No such file or directory: '/home/renato/RESEARCH/patent_analysis/RESEARCH/patent_analysis/var_builder.py'
    Traceback (most recent call last):
      File "/home/renato/anaconda3/lib/python3.8/site-packages/notebook/services/contents/filemanager.py", line 473, in save
        self._save_file(os_path, model['content'], model.get('format'))
      File "/home/renato/anaconda3/lib/python3.8/site-packages/notebook/services/contents/fileio.py", line 340, in _save_file
        with self.atomic_writing(os_path, text=False) as f:
      File "/home/renato/anaconda3/lib/python3.8/contextlib.py", line 113, in __enter__
        return next(self.gen)
      File "/home/renato/anaconda3/lib/python3.8/site-packages/notebook/services/contents/fileio.py", line 210, in atomic_writing
        with atomic_writing(os_path, *args, log=self.log, **kwargs) as f:
      File "/home/renato/anaconda3/lib/python3.8/contextlib.py", line 113, in __enter__
        return next(self.gen)
      File "/home/renato/anaconda3/lib/python3.8/site-packages/notebook/services/contents/fileio.py", line 107, in atomic_writing
        fileobj = io.open(path, 'wb', **kwargs)
    FileNotFoundError: [Errno 2] No such file or directory: '/home/renato/RESEARCH/patent_analysis/RESEARCH/patent_analysis/var_builder.py'
[W 16:01:48.300 NotebookApp] 500 PUT /api/contents/RESEARCH/patent_analysis/var_builder.py (127.0.0.1): Unexpected error while saving file: RESEARCH/patent_analysis/var_builder.py [Errno 2] No such file or directory: '/home/renato/RESEARCH/patent_analysis/RESEARCH/patent_analysis/var_builder.py'
[W 16:01:48.300 NotebookApp] Unexpected error while saving file: RESEARCH/patent_analysis/var_builder.py [Errno 2] No such file or directory: '/home/renato/RESEARCH/patent_analysis/RESEARCH/patent_analysis/var_builder.py'
[E 16:01:48.301 NotebookApp] {
      "Host": "localhost:8080",
      "User-Agent": "Mozilla/5.0 (Windows NT 10.0; Win64; x64; rv:81.0) Gecko/20100101 Firefox/81.0",
      "Accept": "application/json, text/javascript, */*; q=0.01",
      "Accept-Language": "en-US,en;q=0.5",
      "Accept-Encoding": "gzip, deflate",
      "Content-Type": "application/json",
      "X-Xsrftoken": "2|94322795|9b744c6c8443ddb7fe8a96900e6941bd|1602879623",
      "X-Requested-With": "XMLHttpRequest",
      "Content-Length": "6536",
      "Origin": "http://localhost:8080",
      "Dnt": "1",
      "Connection": "keep-alive",
      "Referer": "http://localhost:8080/edit/RESEARCH/patent_analysis/var_builder.py",
      "Cookie": "_xsrf=2|94322795|9b744c6c8443ddb7fe8a96900e6941bd|1602879623; username-localhost-8889=\"2|1:0|10:1602880293|23:username-localhost-8889|44:ZTk0ZjZlMjBjNmE2NDBlN2E3MzY4NzZiNjcyMGExOWI=|c8e7b5827ac161b9b1bf5693eff5020dc0ff1c3041668a70337f594353019564\"; username-localhost-8888=\"2|1:0|10:1603199253|23:username-localhost-8888|44:ZTM4ODI4NTE4NzljNGRhYjg1NzEyZGYyM2Y4ZTE2MGU=|2c39263755d5ff95b3fe6816fe188c8144c17e122238d8b9124912c41a0eb93a\"; username-localhost-8080=\"2|1:0|10:1603888623|23:username-localhost-8080|44:ZDZmM2RhZmVlMjI2NDg3ZDkwN2EwOWY4NjRhMjMxYzY=|67f005c42871523e09257b8463cad5385acf0ed6228ef2a92a8340b3e377a94d\""
    }
[E 16:01:48.301 NotebookApp] 500 PUT /api/contents/RESEARCH/patent_analysis/var_builder.py (127.0.0.1) 2.28ms referer=http://localhost:8080/edit/RESEARCH/patent_analysis/var_builder.py
[W 16:01:51.942 NotebookApp] 404 GET /api/contents/RESEARCH/patent_analysis/var_builder.py?content=0&_=1603995501619 (127.0.0.1): No such file or directory: RESEARCH/patent_analysis/var_builder.py
[W 16:01:51.942 NotebookApp] No such file or directory: RESEARCH/patent_analysis/var_builder.py
[W 16:01:51.942 NotebookApp] 404 GET /api/contents/RESEARCH/patent_analysis/var_builder.py?content=0&_=1603995501619 (127.0.0.1) 1.61ms referer=http://localhost:8080/edit/RESEARCH/patent_analysis/var_builder.py
[I 16:01:52.078 NotebookApp] Uploading file to /RESEARCH/patent_analysis/var_builder.py
[E 16:01:52.078 NotebookApp] Error while saving file: RESEARCH/patent_analysis/var_builder.py [Errno 2] No such file or directory: '/home/renato/RESEARCH/patent_analysis/RESEARCH/patent_analysis/var_builder.py'
    Traceback (most recent call last):
      File "/home/renato/anaconda3/lib/python3.8/site-packages/notebook/services/contents/filemanager.py", line 473, in save
        self._save_file(os_path, model['content'], model.get('format'))
      File "/home/renato/anaconda3/lib/python3.8/site-packages/notebook/services/contents/fileio.py", line 340, in _save_file
        with self.atomic_writing(os_path, text=False) as f:
      File "/home/renato/anaconda3/lib/python3.8/contextlib.py", line 113, in __enter__
        return next(self.gen)
      File "/home/renato/anaconda3/lib/python3.8/site-packages/notebook/services/contents/fileio.py", line 210, in atomic_writing
        with atomic_writing(os_path, *args, log=self.log, **kwargs) as f:
      File "/home/renato/anaconda3/lib/python3.8/contextlib.py", line 113, in __enter__
        return next(self.gen)
      File "/home/renato/anaconda3/lib/python3.8/site-packages/notebook/services/contents/fileio.py", line 107, in atomic_writing
        fileobj = io.open(path, 'wb', **kwargs)
    FileNotFoundError: [Errno 2] No such file or directory: '/home/renato/RESEARCH/patent_analysis/RESEARCH/patent_analysis/var_builder.py'
[W 16:01:52.079 NotebookApp] 500 PUT /api/contents/RESEARCH/patent_analysis/var_builder.py (127.0.0.1): Unexpected error while saving file: RESEARCH/patent_analysis/var_builder.py [Errno 2] No such file or directory: '/home/renato/RESEARCH/patent_analysis/RESEARCH/patent_analysis/var_builder.py'
[W 16:01:52.079 NotebookApp] Unexpected error while saving file: RESEARCH/patent_analysis/var_builder.py [Errno 2] No such file or directory: '/home/renato/RESEARCH/patent_analysis/RESEARCH/patent_analysis/var_builder.py'
[E 16:01:52.080 NotebookApp] {
      "Host": "localhost:8080",
      "User-Agent": "Mozilla/5.0 (Windows NT 10.0; Win64; x64; rv:81.0) Gecko/20100101 Firefox/81.0",
      "Accept": "application/json, text/javascript, */*; q=0.01",
      "Accept-Language": "en-US,en;q=0.5",
      "Accept-Encoding": "gzip, deflate",
      "Content-Type": "application/json",
      "X-Xsrftoken": "2|94322795|9b744c6c8443ddb7fe8a96900e6941bd|1602879623",
      "X-Requested-With": "XMLHttpRequest",
      "Content-Length": "6536",
      "Origin": "http://localhost:8080",
      "Dnt": "1",
      "Connection": "keep-alive",
      "Referer": "http://localhost:8080/edit/RESEARCH/patent_analysis/var_builder.py",
      "Cookie": "_xsrf=2|94322795|9b744c6c8443ddb7fe8a96900e6941bd|1602879623; username-localhost-8889=\"2|1:0|10:1602880293|23:username-localhost-8889|44:ZTk0ZjZlMjBjNmE2NDBlN2E3MzY4NzZiNjcyMGExOWI=|c8e7b5827ac161b9b1bf5693eff5020dc0ff1c3041668a70337f594353019564\"; username-localhost-8888=\"2|1:0|10:1603199253|23:username-localhost-8888|44:ZTM4ODI4NTE4NzljNGRhYjg1NzEyZGYyM2Y4ZTE2MGU=|2c39263755d5ff95b3fe6816fe188c8144c17e122238d8b9124912c41a0eb93a\"; username-localhost-8080=\"2|1:0|10:1603888623|23:username-localhost-8080|44:ZDZmM2RhZmVlMjI2NDg3ZDkwN2EwOWY4NjRhMjMxYzY=|67f005c42871523e09257b8463cad5385acf0ed6228ef2a92a8340b3e377a94d\""
    }
[E 16:01:52.080 NotebookApp] 500 PUT /api/contents/RESEARCH/patent_analysis/var_builder.py (127.0.0.1) 2.55ms referer=http://localhost:8080/edit/RESEARCH/patent_analysis/var_builder.py
[W 16:02:05.136 NotebookApp] 404 GET /api/contents/RESEARCH/patent_analysis?type=directory&_=1603985603418 (127.0.0.1): No such file or directory: RESEARCH/patent_analysis
[W 16:02:05.136 NotebookApp] No such file or directory: RESEARCH/patent_analysis
[W 16:02:05.137 NotebookApp] 404 GET /api/contents/RESEARCH/patent_analysis?type=directory&_=1603985603418 (127.0.0.1) 1.50ms referer=http://localhost:8080/tree/RESEARCH/patent_analysis
[W 16:02:05.750 NotebookApp] 404 GET /tree/RESEARCH/patent_analysis (127.0.0.1) 185.32ms referer=None
[I 16:02:18.197 NotebookApp] 302 GET / (127.0.0.1) 0.67ms
[I 16:02:58.091 NotebookApp] Saving file at /var_builder.py
[I 16:03:44.849 NotebookApp] Saving file at /var_builder.py
[I 16:05:35.803 NotebookApp] Saving file at /var_builder.py
[I 16:10:44.629 NotebookApp] Saving file at /var_builder.py
Traceback (most recent call last):
  File "var_builder.py", line 117, in <module>
    df=df.merge(pt_df, how='inner', left_index=True)
  File "/home/ubuntu/anaconda3/lib/python3.7/site-packages/dask/dataframe/core.py", line 3906, in merge
    shuffle=shuffle,
  File "/home/ubuntu/anaconda3/lib/python3.7/site-packages/dask/dataframe/multi.py", line 493, in merge
    indicator=indicator,
  File "/home/ubuntu/anaconda3/lib/python3.7/site-packages/dask/dataframe/multi.py", line 324, in single_partition_join
    meta = left._meta_nonempty.merge(right._meta_nonempty, **kwargs)
  File "/home/ubuntu/anaconda3/lib/python3.7/site-packages/pandas/core/frame.py", line 7297, in merge
    validate=validate,
  File "/home/ubuntu/anaconda3/lib/python3.7/site-packages/pandas/core/reshape/merge.py", line 86, in merge
    validate=validate,
  File "/home/ubuntu/anaconda3/lib/python3.7/site-packages/pandas/core/reshape/merge.py", line 620, in __init__
    self._validate_specification()
  File "/home/ubuntu/anaconda3/lib/python3.7/site-packages/pandas/core/reshape/merge.py", line 1183, in _validate_specification
    raise MergeError("Must pass right_on or right_index=True")
pandas.errors.MergeError: Must pass right_on or right_index=True
[I 09:55:45.366 NotebookApp] JupyterLab extension loaded from /home/renato/anaconda3/lib/python3.7/site-packages/jupyterlab
[I 09:55:45.366 NotebookApp] JupyterLab application directory is /home/renato/anaconda3/share/jupyter/lab
[I 09:55:45.368 NotebookApp] Serving notebooks from local directory: /home/renato/RESEARCH/patent_analysis
[I 09:55:45.368 NotebookApp] Jupyter Notebook 6.1.4 is running at:
[I 09:55:45.368 NotebookApp] http://localhost:8888/?token=dd5d302bbea590d21cb61947cd59d7489667af33ba20ef8d
[I 09:55:45.368 NotebookApp]  or http://127.0.0.1:8888/?token=dd5d302bbea590d21cb61947cd59d7489667af33ba20ef8d
[I 09:55:45.368 NotebookApp] Use Control-C to stop this server and shut down all kernels (twice to skip confirmation).
[W 09:55:45.372 NotebookApp] No web browser found: could not locate runnable browser.
[C 09:55:45.372 NotebookApp] 
    
    To access the notebook, open this file in a browser:
        file:///home/renato/.local/share/jupyter/runtime/nbserver-154576-open.html
    Or copy and paste one of these URLs:
        http://localhost:8888/?token=dd5d302bbea590d21cb61947cd59d7489667af33ba20ef8d
     or http://127.0.0.1:8888/?token=dd5d302bbea590d21cb61947cd59d7489667af33ba20ef8d
[W 09:55:51.731 NotebookApp] 404 GET /notebooks/RESEARCH/patent_analysis/cleanpat_parquet_to_csv.ipynb (127.0.0.1): No such file or directory: RESEARCH/patent_analysis/cleanpat_parquet_to_csv.ipynb
[W 09:55:51.761 NotebookApp] 404 GET /notebooks/RESEARCH/patent_analysis/cleanpat_parquet_to_csv.ipynb (127.0.0.1) 31.65ms referer=http://localhost:8889/tree/RESEARCH/patent_analysis
[W 09:55:55.152 NotebookApp] 404 GET /api/contents/RESEARCH/patent_analysis?type=directory&_=1606391549066 (127.0.0.1): No such file or directory: RESEARCH/patent_analysis
[W 09:55:55.153 NotebookApp] No such file or directory: RESEARCH/patent_analysis
[W 09:55:55.153 NotebookApp] 404 GET /api/contents/RESEARCH/patent_analysis?type=directory&_=1606391549066 (127.0.0.1) 1.11ms referer=http://localhost:8889/tree/RESEARCH/patent_analysis
[W 09:56:06.467 NotebookApp] 404 GET /notebooks/RESEARCH/patent_analysis/cleanpat_parquet_to_csv.ipynb (127.0.0.1): No such file or directory: RESEARCH/patent_analysis/cleanpat_parquet_to_csv.ipynb
[W 09:56:06.468 NotebookApp] 404 GET /notebooks/RESEARCH/patent_analysis/cleanpat_parquet_to_csv.ipynb (127.0.0.1) 2.23ms referer=http://localhost:8889/tree/RESEARCH/patent_analysis
[W 09:56:09.548 NotebookApp] 404 GET /api/contents/RESEARCH/patent_analysis?type=directory&_=1606391549069 (127.0.0.1): No such file or directory: RESEARCH/patent_analysis
[W 09:56:09.548 NotebookApp] No such file or directory: RESEARCH/patent_analysis
[W 09:56:09.549 NotebookApp] 404 GET /api/contents/RESEARCH/patent_analysis?type=directory&_=1606391549069 (127.0.0.1) 1.43ms referer=http://localhost:8889/tree/RESEARCH/patent_analysis
[W 09:56:10.530 NotebookApp] 404 GET /tree/RESEARCH/patent_analysis (127.0.0.1) 2.18ms referer=None
[W 09:56:39.205 NotebookApp] 404 GET /tree/RESEARCH/patent_analysis (127.0.0.1) 2.06ms referer=None
[I 09:57:18.355 NotebookApp] 302 GET / (127.0.0.1) 0.68ms
[I 09:57:38.510 NotebookApp] Kernel started: 84a1ba59-eaf4-40ae-b296-5685ef03cd94, name: python3
[I 09:59:37.984 NotebookApp] Saving file at /cleanpat_parquet_to_csv.ipynb
[I 09:59:40.894 NotebookApp] Saving file at /graph_tool-v2.py
[I 10:00:01.770 NotebookApp] Kernel interrupted: 84a1ba59-eaf4-40ae-b296-5685ef03cd94
[I 10:00:14.649 NotebookApp] Saving file at /cleanpat_parquet_to_csv.ipynb
[I 10:00:19.424 NotebookApp] Starting buffering for 84a1ba59-eaf4-40ae-b296-5685ef03cd94:020a8e23214b443781e7159b0a59d87c
[I 10:00:25.560 NotebookApp] Kernel restarted: 84a1ba59-eaf4-40ae-b296-5685ef03cd94
[I 10:00:25.666 NotebookApp] Restoring connection for 84a1ba59-eaf4-40ae-b296-5685ef03cd94:020a8e23214b443781e7159b0a59d87c
[I 10:00:25.666 NotebookApp] Replaying 17 buffered messages
[I 10:01:37.982 NotebookApp] Saving file at /cleanpat_parquet_to_csv.ipynb
[I 10:07:38.045 NotebookApp] Saving file at /cleanpat_parquet_to_csv.ipynb
[I 10:08:27.862 NotebookApp] Saving file at /cleanpat_parquet_to_csv.ipynb
[I 10:08:49.889 NotebookApp] Starting buffering for 84a1ba59-eaf4-40ae-b296-5685ef03cd94:020a8e23214b443781e7159b0a59d87c
[I 10:08:50.431 NotebookApp] Kernel restarted: 84a1ba59-eaf4-40ae-b296-5685ef03cd94
[I 10:08:50.514 NotebookApp] Restoring connection for 84a1ba59-eaf4-40ae-b296-5685ef03cd94:020a8e23214b443781e7159b0a59d87c
[I 10:08:50.514 NotebookApp] Replaying 3 buffered messages
[I 10:09:03.112 NotebookApp] Kernel interrupted: 84a1ba59-eaf4-40ae-b296-5685ef03cd94
[I 10:09:13.075 NotebookApp] Starting buffering for 84a1ba59-eaf4-40ae-b296-5685ef03cd94:020a8e23214b443781e7159b0a59d87c
[I 10:09:13.786 NotebookApp] Kernel restarted: 84a1ba59-eaf4-40ae-b296-5685ef03cd94
[I 10:09:13.879 NotebookApp] Restoring connection for 84a1ba59-eaf4-40ae-b296-5685ef03cd94:020a8e23214b443781e7159b0a59d87c
[I 10:09:13.880 NotebookApp] Replaying 3 buffered messages
[I 10:09:38.653 NotebookApp] Saving file at /cleanpat_parquet_to_csv.ipynb
[I 10:15:46.118 NotebookApp] Saving file at /cleanpat_parquet_to_csv.ipynb
[I 10:23:38.838 NotebookApp] Saving file at /cleanpat_parquet_to_csv.ipynb
[I 10:23:41.984 NotebookApp] Kernel interrupted: 84a1ba59-eaf4-40ae-b296-5685ef03cd94
[I 10:24:14.984 NotebookApp] Saving file at /cleanpat_parquet_to_csv.ipynb
[I 10:24:17.740 NotebookApp] Starting buffering for 84a1ba59-eaf4-40ae-b296-5685ef03cd94:020a8e23214b443781e7159b0a59d87c
[I 10:24:24.261 NotebookApp] Kernel restarted: 84a1ba59-eaf4-40ae-b296-5685ef03cd94
[I 10:24:24.423 NotebookApp] Restoring connection for 84a1ba59-eaf4-40ae-b296-5685ef03cd94:020a8e23214b443781e7159b0a59d87c
[I 10:25:38.725 NotebookApp] Saving file at /cleanpat_parquet_to_csv.ipynb
[I 10:27:38.824 NotebookApp] Saving file at /cleanpat_parquet_to_csv.ipynb
[I 10:29:38.847 NotebookApp] Saving file at /cleanpat_parquet_to_csv.ipynb
[W 10:35:45.340 NotebookApp] Notebook clean_uspatentcitation.ipynb is not trusted
[I 10:35:46.504 NotebookApp] Kernel started: 892cc6b4-dfac-4203-97a0-a32c23ea3523, name: python3
[I 10:37:38.741 NotebookApp] Saving file at /cleanpat_parquet_to_csv.ipynb
[I 10:39:38.744 NotebookApp] Saving file at /cleanpat_parquet_to_csv.ipynb
[I 10:40:29.082 NotebookApp] Starting buffering for 84a1ba59-eaf4-40ae-b296-5685ef03cd94:020a8e23214b443781e7159b0a59d87c
[I 10:40:34.756 NotebookApp] Kernel restarted: 84a1ba59-eaf4-40ae-b296-5685ef03cd94
[I 10:40:34.900 NotebookApp] Restoring connection for 84a1ba59-eaf4-40ae-b296-5685ef03cd94:020a8e23214b443781e7159b0a59d87c
[I 10:40:34.900 NotebookApp] Replaying 3 buffered messages
[I 10:40:36.793 NotebookApp] Kernel interrupted: 84a1ba59-eaf4-40ae-b296-5685ef03cd94
[I 10:40:45.044 NotebookApp] Starting buffering for 84a1ba59-eaf4-40ae-b296-5685ef03cd94:020a8e23214b443781e7159b0a59d87c
[I 10:40:45.587 NotebookApp] Kernel restarted: 84a1ba59-eaf4-40ae-b296-5685ef03cd94
[I 10:40:45.672 NotebookApp] Restoring connection for 84a1ba59-eaf4-40ae-b296-5685ef03cd94:020a8e23214b443781e7159b0a59d87c
[I 10:40:45.672 NotebookApp] Replaying 3 buffered messages
[I 10:41:38.742 NotebookApp] Saving file at /cleanpat_parquet_to_csv.ipynb
[I 10:43:38.726 NotebookApp] Saving file at /cleanpat_parquet_to_csv.ipynb
[I 10:45:39.035 NotebookApp] Saving file at /cleanpat_parquet_to_csv.ipynb
[I 10:51:38.817 NotebookApp] Saving file at /cleanpat_parquet_to_csv.ipynb
[I 11:01:43.685 NotebookApp] Saving file at /cleanpat_parquet_to_csv.ipynb
[I 11:03:38.727 NotebookApp] Saving file at /cleanpat_parquet_to_csv.ipynb
[I 11:04:48.366 NotebookApp] Kernel interrupted: 84a1ba59-eaf4-40ae-b296-5685ef03cd94
[I 11:05:12.589 NotebookApp] KernelRestarter: restarting kernel (1/5), keep random ports
kernel 84a1ba59-eaf4-40ae-b296-5685ef03cd94 restarted
[I 11:05:28.864 NotebookApp] Kernel started: 2a16a027-5df8-4d5c-8748-2e11c63d9acb, name: python3
[I 11:05:38.791 NotebookApp] Saving file at /cleanpat_parquet_to_csv.ipynb
[I 11:07:27.969 NotebookApp] Saving file at /check_centrality.ipynb
[I 11:17:04.947 NotebookApp] Kernel interrupted: 84a1ba59-eaf4-40ae-b296-5685ef03cd94
[I 11:17:31.392 NotebookApp] Kernel interrupted: 84a1ba59-eaf4-40ae-b296-5685ef03cd94
[I 11:17:38.734 NotebookApp] Saving file at /cleanpat_parquet_to_csv.ipynb
[I 11:19:39.014 NotebookApp] Saving file at /cleanpat_parquet_to_csv.ipynb
[I 11:19:45.102 NotebookApp] Kernel interrupted: 84a1ba59-eaf4-40ae-b296-5685ef03cd94
[I 11:21:39.272 NotebookApp] Saving file at /cleanpat_parquet_to_csv.ipynb
[I 11:22:03.628 NotebookApp] KernelRestarter: restarting kernel (1/5), keep random ports
kernel 84a1ba59-eaf4-40ae-b296-5685ef03cd94 restarted
[I 11:23:38.792 NotebookApp] Saving file at /cleanpat_parquet_to_csv.ipynb
[I 11:25:38.776 NotebookApp] Saving file at /cleanpat_parquet_to_csv.ipynb
[I 11:27:38.820 NotebookApp] Saving file at /cleanpat_parquet_to_csv.ipynb
[I 11:28:43.001 NotebookApp] Starting buffering for 2a16a027-5df8-4d5c-8748-2e11c63d9acb:fe1f68eeca274ff58c881f994c4e7e05
[I 11:28:43.670 NotebookApp] Kernel restarted: 2a16a027-5df8-4d5c-8748-2e11c63d9acb
[I 11:28:43.752 NotebookApp] Restoring connection for 2a16a027-5df8-4d5c-8748-2e11c63d9acb:fe1f68eeca274ff58c881f994c4e7e05
[I 11:28:43.752 NotebookApp] Replaying 3 buffered messages
[I 11:29:28.036 NotebookApp] Saving file at /check_centrality.ipynb
[I 11:38:11.121 NotebookApp] Saving file at /graph_tool-v2.py
[I 11:39:35.834 NotebookApp] Saving file at /graph_tool-v2.py
[I 11:55:28.290 NotebookApp] Saving file at /check_centrality.ipynb
[I 11:59:28.261 NotebookApp] Saving file at /check_centrality.ipynb
[I 12:01:38.978 NotebookApp] Saving file at /cleanpat_parquet_to_csv.ipynb
[I 12:03:38.996 NotebookApp] Saving file at /cleanpat_parquet_to_csv.ipynb
[I 12:05:38.971 NotebookApp] Saving file at /cleanpat_parquet_to_csv.ipynb
[I 12:09:39.036 NotebookApp] Saving file at /cleanpat_parquet_to_csv.ipynb
[I 12:11:39.051 NotebookApp] Saving file at /cleanpat_parquet_to_csv.ipynb
[I 12:13:39.061 NotebookApp] Saving file at /cleanpat_parquet_to_csv.ipynb
[I 12:15:39.040 NotebookApp] Saving file at /cleanpat_parquet_to_csv.ipynb
[I 12:19:39.083 NotebookApp] Saving file at /cleanpat_parquet_to_csv.ipynb
[I 12:21:39.079 NotebookApp] Saving file at /cleanpat_parquet_to_csv.ipynb
[I 12:23:39.031 NotebookApp] Saving file at /cleanpat_parquet_to_csv.ipynb
[I 12:25:39.538 NotebookApp] Saving file at /cleanpat_parquet_to_csv.ipynb
[I 12:27:39.340 NotebookApp] Saving file at /cleanpat_parquet_to_csv.ipynb
[I 12:33:40.583 NotebookApp] Saving file at /cleanpat_parquet_to_csv.ipynb
[I 12:35:39.313 NotebookApp] Saving file at /cleanpat_parquet_to_csv.ipynb
[I 12:35:57.681 NotebookApp] KernelRestarter: restarting kernel (1/5), keep random ports
kernel 84a1ba59-eaf4-40ae-b296-5685ef03cd94 restarted
[I 12:37:39.319 NotebookApp] Saving file at /cleanpat_parquet_to_csv.ipynb
[I 12:39:28.473 NotebookApp] Saving file at /check_centrality.ipynb
[I 12:39:39.606 NotebookApp] Saving file at /cleanpat_parquet_to_csv.ipynb
[I 12:41:39.343 NotebookApp] Saving file at /cleanpat_parquet_to_csv.ipynb
[I 12:43:28.601 NotebookApp] Saving file at /check_centrality.ipynb
[I 13:02:38.059 NotebookApp] Kernel started: 7a8b06c7-3e16-423b-9124-8e59f6ed99dc, name: python3
[I 13:03:28.546 NotebookApp] Saving file at /check_centrality.ipynb
[I 13:04:37.755 NotebookApp] Saving file at /dataset.ipynb
[I 13:06:37.835 NotebookApp] Saving file at /dataset.ipynb
[I 13:08:37.725 NotebookApp] Saving file at /dataset.ipynb
[I 13:10:37.737 NotebookApp] Saving file at /dataset.ipynb
[I 13:34:37.887 NotebookApp] Saving file at /dataset.ipynb
[I 13:35:54.142 NotebookApp] Saving file at /dataset.ipynb
[I 13:35:59.070 NotebookApp] Starting buffering for 7a8b06c7-3e16-423b-9124-8e59f6ed99dc:2faa151884844283bae3abfdd538d836
[I 13:35:59.334 NotebookApp] Kernel restarted: 7a8b06c7-3e16-423b-9124-8e59f6ed99dc
[I 13:35:59.493 NotebookApp] Restoring connection for 7a8b06c7-3e16-423b-9124-8e59f6ed99dc:2faa151884844283bae3abfdd538d836
[I 13:35:59.493 NotebookApp] Replaying 3 buffered messages
[I 13:36:18.094 NotebookApp] Saving file at /dataset.ipynb
[I 13:36:20.596 NotebookApp] Starting buffering for 7a8b06c7-3e16-423b-9124-8e59f6ed99dc:2faa151884844283bae3abfdd538d836
[I 13:36:21.025 NotebookApp] Kernel restarted: 7a8b06c7-3e16-423b-9124-8e59f6ed99dc
[I 13:36:21.093 NotebookApp] Restoring connection for 7a8b06c7-3e16-423b-9124-8e59f6ed99dc:2faa151884844283bae3abfdd538d836
[I 13:36:21.093 NotebookApp] Replaying 3 buffered messages
[I 13:36:37.852 NotebookApp] Saving file at /dataset.ipynb
[I 13:37:14.189 NotebookApp] Starting buffering for 7a8b06c7-3e16-423b-9124-8e59f6ed99dc:2faa151884844283bae3abfdd538d836
[I 13:37:14.607 NotebookApp] Kernel restarted: 7a8b06c7-3e16-423b-9124-8e59f6ed99dc
[I 13:37:14.724 NotebookApp] Restoring connection for 7a8b06c7-3e16-423b-9124-8e59f6ed99dc:2faa151884844283bae3abfdd538d836
[I 13:37:14.724 NotebookApp] Replaying 3 buffered messages
[I 13:37:43.284 NotebookApp] Starting buffering for 7a8b06c7-3e16-423b-9124-8e59f6ed99dc:2faa151884844283bae3abfdd538d836
[I 13:37:43.837 NotebookApp] Kernel restarted: 7a8b06c7-3e16-423b-9124-8e59f6ed99dc
[I 13:37:43.918 NotebookApp] Restoring connection for 7a8b06c7-3e16-423b-9124-8e59f6ed99dc:2faa151884844283bae3abfdd538d836
[I 13:37:43.918 NotebookApp] Replaying 3 buffered messages
[I 13:38:37.846 NotebookApp] Saving file at /dataset.ipynb
[I 13:39:21.269 NotebookApp] Starting buffering for 7a8b06c7-3e16-423b-9124-8e59f6ed99dc:2faa151884844283bae3abfdd538d836
[I 13:39:22.112 NotebookApp] Kernel restarted: 7a8b06c7-3e16-423b-9124-8e59f6ed99dc
[I 13:39:22.196 NotebookApp] Restoring connection for 7a8b06c7-3e16-423b-9124-8e59f6ed99dc:2faa151884844283bae3abfdd538d836
[I 13:39:22.197 NotebookApp] Replaying 3 buffered messages
[I 13:39:31.380 NotebookApp] Starting buffering for 7a8b06c7-3e16-423b-9124-8e59f6ed99dc:2faa151884844283bae3abfdd538d836
[I 13:39:31.798 NotebookApp] Kernel restarted: 7a8b06c7-3e16-423b-9124-8e59f6ed99dc
[I 13:39:31.879 NotebookApp] Restoring connection for 7a8b06c7-3e16-423b-9124-8e59f6ed99dc:2faa151884844283bae3abfdd538d836
[I 13:39:31.880 NotebookApp] Replaying 3 buffered messages
[I 13:40:01.101 NotebookApp] Starting buffering for 7a8b06c7-3e16-423b-9124-8e59f6ed99dc:2faa151884844283bae3abfdd538d836
[I 13:40:01.818 NotebookApp] Kernel restarted: 7a8b06c7-3e16-423b-9124-8e59f6ed99dc
[I 13:40:01.909 NotebookApp] Restoring connection for 7a8b06c7-3e16-423b-9124-8e59f6ed99dc:2faa151884844283bae3abfdd538d836
[I 13:40:01.909 NotebookApp] Replaying 3 buffered messages
[I 13:40:37.976 NotebookApp] Saving file at /dataset.ipynb
[I 13:42:37.891 NotebookApp] Saving file at /dataset.ipynb
[I 13:44:38.487 NotebookApp] Saving file at /dataset.ipynb
[I 13:46:39.157 NotebookApp] Saving file at /dataset.ipynb
[I 13:48:37.982 NotebookApp] Saving file at /dataset.ipynb
[I 13:49:50.038 NotebookApp] Starting buffering for 7a8b06c7-3e16-423b-9124-8e59f6ed99dc:2faa151884844283bae3abfdd538d836
[I 13:49:50.881 NotebookApp] Kernel restarted: 7a8b06c7-3e16-423b-9124-8e59f6ed99dc
[I 13:49:50.974 NotebookApp] Restoring connection for 7a8b06c7-3e16-423b-9124-8e59f6ed99dc:2faa151884844283bae3abfdd538d836
[I 13:49:50.974 NotebookApp] Replaying 3 buffered messages
[I 13:50:37.929 NotebookApp] Saving file at /dataset.ipynb
[I 13:58:37.982 NotebookApp] Saving file at /dataset.ipynb
[I 14:00:37.991 NotebookApp] Saving file at /dataset.ipynb
[I 14:02:38.002 NotebookApp] Saving file at /dataset.ipynb
[I 14:04:38.173 NotebookApp] Saving file at /dataset.ipynb
[I 14:05:03.418 NotebookApp] Starting buffering for 7a8b06c7-3e16-423b-9124-8e59f6ed99dc:2faa151884844283bae3abfdd538d836
[I 14:05:04.160 NotebookApp] Kernel restarted: 7a8b06c7-3e16-423b-9124-8e59f6ed99dc
[I 14:05:04.242 NotebookApp] Restoring connection for 7a8b06c7-3e16-423b-9124-8e59f6ed99dc:2faa151884844283bae3abfdd538d836
[I 14:05:04.243 NotebookApp] Replaying 3 buffered messages
[I 14:06:38.009 NotebookApp] Saving file at /dataset.ipynb
[I 14:06:53.494 NotebookApp] Starting buffering for 7a8b06c7-3e16-423b-9124-8e59f6ed99dc:2faa151884844283bae3abfdd538d836
[I 14:06:54.233 NotebookApp] Kernel restarted: 7a8b06c7-3e16-423b-9124-8e59f6ed99dc
[I 14:06:54.327 NotebookApp] Restoring connection for 7a8b06c7-3e16-423b-9124-8e59f6ed99dc:2faa151884844283bae3abfdd538d836
[I 14:06:54.327 NotebookApp] Replaying 3 buffered messages
[I 14:08:38.018 NotebookApp] Saving file at /dataset.ipynb
[I 14:08:54.223 NotebookApp] Starting buffering for 7a8b06c7-3e16-423b-9124-8e59f6ed99dc:2faa151884844283bae3abfdd538d836
[I 14:08:54.949 NotebookApp] Kernel restarted: 7a8b06c7-3e16-423b-9124-8e59f6ed99dc
[I 14:08:55.047 NotebookApp] Restoring connection for 7a8b06c7-3e16-423b-9124-8e59f6ed99dc:2faa151884844283bae3abfdd538d836
[I 14:08:55.047 NotebookApp] Replaying 3 buffered messages
[I 14:10:38.031 NotebookApp] Saving file at /dataset.ipynb
[I 14:16:38.111 NotebookApp] Saving file at /dataset.ipynb
[I 14:22:46.180 NotebookApp] Saving file at /dataset.ipynb
[I 14:22:50.007 NotebookApp] Starting buffering for 7a8b06c7-3e16-423b-9124-8e59f6ed99dc:2faa151884844283bae3abfdd538d836
[I 14:22:54.190 NotebookApp] Kernel restarted: 7a8b06c7-3e16-423b-9124-8e59f6ed99dc
[I 14:22:54.307 NotebookApp] Restoring connection for 7a8b06c7-3e16-423b-9124-8e59f6ed99dc:2faa151884844283bae3abfdd538d836
[I 14:22:54.307 NotebookApp] Replaying 3 buffered messages
[I 14:24:38.045 NotebookApp] Saving file at /dataset.ipynb
[I 14:30:38.131 NotebookApp] Saving file at /dataset.ipynb
[I 14:33:40.168 NotebookApp] Starting buffering for 7a8b06c7-3e16-423b-9124-8e59f6ed99dc:2faa151884844283bae3abfdd538d836
[I 14:33:44.144 NotebookApp] Kernel restarted: 7a8b06c7-3e16-423b-9124-8e59f6ed99dc
[I 14:33:44.238 NotebookApp] Restoring connection for 7a8b06c7-3e16-423b-9124-8e59f6ed99dc:2faa151884844283bae3abfdd538d836
[I 14:33:44.238 NotebookApp] Replaying 3 buffered messages
[I 14:34:05.232 NotebookApp] Starting buffering for 7a8b06c7-3e16-423b-9124-8e59f6ed99dc:2faa151884844283bae3abfdd538d836
[I 14:34:05.956 NotebookApp] Kernel restarted: 7a8b06c7-3e16-423b-9124-8e59f6ed99dc
[I 14:34:06.041 NotebookApp] Restoring connection for 7a8b06c7-3e16-423b-9124-8e59f6ed99dc:2faa151884844283bae3abfdd538d836
[I 14:34:06.041 NotebookApp] Replaying 3 buffered messages
[I 14:34:38.070 NotebookApp] Saving file at /dataset.ipynb
[I 14:40:38.192 NotebookApp] Saving file at /dataset.ipynb
[I 14:41:05.733 NotebookApp] Kernel interrupted: 7a8b06c7-3e16-423b-9124-8e59f6ed99dc
[I 14:42:38.193 NotebookApp] Saving file at /dataset.ipynb
[I 14:42:53.363 NotebookApp] Saving file at /dataset.ipynb
[I 14:42:59.227 NotebookApp] Starting buffering for 7a8b06c7-3e16-423b-9124-8e59f6ed99dc:2faa151884844283bae3abfdd538d836
[I 14:43:02.887 NotebookApp] Kernel restarted: 7a8b06c7-3e16-423b-9124-8e59f6ed99dc
[I 14:43:03.013 NotebookApp] Restoring connection for 7a8b06c7-3e16-423b-9124-8e59f6ed99dc:2faa151884844283bae3abfdd538d836
[I 14:43:03.013 NotebookApp] Replaying 3 buffered messages
[I 14:44:38.140 NotebookApp] Saving file at /dataset.ipynb
[I 14:46:38.157 NotebookApp] Saving file at /dataset.ipynb
[I 14:52:38.172 NotebookApp] Saving file at /dataset.ipynb
[I 15:09:07.769 NotebookApp] Kernel started: 7a421367-1cb0-4e45-8258-fb906d4b2563, name: python3
[I 15:12:47.797 NotebookApp] Saving file at /generality.ipynb
[I 15:12:56.106 NotebookApp] Starting buffering for 7a421367-1cb0-4e45-8258-fb906d4b2563:4c6c192ab0db47e082f19a2fa3608084
[I 15:12:56.461 NotebookApp] Kernel restarted: 7a421367-1cb0-4e45-8258-fb906d4b2563
[I 15:12:56.631 NotebookApp] Restoring connection for 7a421367-1cb0-4e45-8258-fb906d4b2563:4c6c192ab0db47e082f19a2fa3608084
[I 15:12:56.631 NotebookApp] Replaying 3 buffered messages
